<?xml version="1.0" encoding="utf-8"?>
<!-- This URDF was automatically created by SolidWorks to URDF Exporter! Originally created by Stephen Brawner (brawner@gmail.com) 
     Commit Version: 1.6.0-1-g15f4949  Build Version: 1.6.7594.29634
     For more information, please see http://wiki.ros.org/sw_urdf_exporter -->
<robot
  name="robot_19">
  <link
    name="base_link">
    <inertial>
      <origin
        xyz="-0.00015122 0.036523 -6.678E-16"
        rpy="0 0 0" />
      <mass
        value="5" />
      <inertia
        ixx="0.09845"
        ixy="0.0038461"
        ixz="2.303E-17"
        iyy="0.22964"
        iyz="2.4544E-19"
        izz="0.1456" />
    </inertial>
    <visual>
      <origin
        xyz="0 0 0"
        rpy="0 0 0" />
      <geometry>
        <mesh
          filename="package://robot_19/meshes/base_link.STL" />
      </geometry>
      <material
        name="">
        <color
          rgba="0.79216 0.81961 0.93333 1" />
      </material>
    </visual>
    <collision>
      <origin
        xyz="0 0 0"
        rpy="0 0 0" />
      <geometry>
        <mesh
          filename="package://robot_19/meshes/base_link.STL" />
      </geometry>
    </collision>
  </link>
  <link
    name="L_link">
    <inertial>
      <origin
        xyz="2.7756E-17 3.4694E-18 -0.015"
        rpy="0 0 0" />
      <mass
        value="0.92127" />
      <inertia
        ixx="0.0024241"
        ixy="0"
        ixz="3.1807E-19"
        iyy="0.0024241"
        iyz="-2.4632E-20"
        izz="0.00471" />
    </inertial>
    <visual>
      <origin
        xyz="0 0 0"
        rpy="0 0 0" />
      <geometry>
        <mesh
          filename="package://robot_19/meshes/L_link.STL" />
      </geometry>
      <material
        name="">
        <color
          rgba="0.79216 0.81961 0.93333 1" />
      </material>
    </visual>
    <collision>
      <origin
        xyz="0 0 0"
        rpy="0 0 0" />
      <geometry>
        <mesh
          filename="package://robot_19/meshes/L_link.STL" />
      </geometry>
    </collision>
  </link>
  <joint
    name="L_joint"
    type="continuous">
    <origin
      xyz="-0.15093 0.175 0.04"
      rpy="1.5708 0.11368 0" />
    <parent
      link="base_link" />
    <child
      link="L_link" />
    <axis
      xyz="0 0 -1" />
  </joint>
  <link
    name="R_link">
    <inertial>
      <origin
        xyz="0 0 0.015"
        rpy="0 0 0" />
      <mass
        value="0.92127" />
      <inertia
        ixx="0.0024241"
        ixy="-1.0842E-19"
        ixz="-4.0664E-19"
        iyy="0.0024241"
        iyz="3.1533E-21"
        izz="0.00471" />
    </inertial>
    <visual>
      <origin
        xyz="0 0 0"
        rpy="0 0 0" />
      <geometry>
        <mesh
          filename="package://robot_19/meshes/R_link.STL" />
      </geometry>
      <material
        name="">
        <color
          rgba="0.79216 0.81961 0.93333 1" />
      </material>
    </visual>
    <collision>
      <origin
        xyz="0 0 0"
        rpy="0 0 0" />
      <geometry>
        <mesh
          filename="package://robot_19/meshes/R_link.STL" />
      </geometry>
    </collision>
  </link>
  <joint
    name="R_joint"
    type="continuous">
    <origin
      xyz="-0.15093 -0.175 0.04"
      rpy="-1.5708 0.19296 -3.1416" />
    <parent
      link="base_link" />
    <child
      link="R_link" />
    <axis
      xyz="0 0 -1" />
  </joint>
  <link
    name="Gripper_link">
    <inertial>
      <origin
        xyz="0.0016471 -0.155 0.062648"
        rpy="0 0 0" />
      <mass
        value="0.27654" />
      <inertia
        ixx="0.003447"
        ixy="1.3053E-18"
        ixz="1.8299E-05"
        iyy="0.00038921"
        iyz="1.5681E-19"
        izz="0.003189" />
    </inertial>
    <visual>
      <origin
        xyz="0 0 0"
        rpy="0 0 0" />
      <geometry>
        <mesh
          filename="package://robot_19/meshes/Gripper_link.STL" />
      </geometry>
      <material
        name="">
        <color
          rgba="0.79216 0.81961 0.93333 1" />
      </material>
    </visual>
    <collision>
      <origin
        xyz="0 0 0"
        rpy="0 0 0" />
      <geometry>
        <mesh
          filename="package://robot_19/meshes/Gripper_link.STL" />
      </geometry>
    </collision>
  </link>
  <joint
    name="Gripper_joint"
    type="fixed">
    <origin
      xyz="0.21093 0.155 -0.05"
      rpy="0 0 0" />
    <parent
      link="base_link" />
    <child
      link="Gripper_link" />
    <axis
      xyz="0 0 0" />
  </joint>
  <link
    name="S_link">
    <inertial>
      <origin
        xyz="0.155 -0.1618 0.12238"
        rpy="0 0 0" />
      <mass
        value="0.56039" />
      <inertia
        ixx="0.0044382"
        ixy="-8.456E-11"
        ixz="2.8428E-11"
        iyy="0.010672"
        iyz="0.0012613"
        izz="0.012536" />
    </inertial>
    <visual>
      <origin
        xyz="0 0 0"
        rpy="0 0 0" />
      <geometry>
        <mesh
          filename="package://robot_19/meshes/S_link.STL" />
      </geometry>
      <material
        name="">
        <color
          rgba="0.79216 0.81961 0.93333 1" />
      </material>
    </visual>
    <collision>
      <origin
        xyz="0 0 0"
        rpy="0 0 0" />
      <geometry>
        <mesh
          filename="package://robot_19/meshes/S_link.STL" />
      </geometry>
    </collision>
  </link>
  <joint
    name="Slider_joint"
    type="revolute">
    <origin
      xyz="0.04 0 0.11"
      rpy="0.41605 0 -1.5708" />
    <parent
      link="Gripper_link" />
    <child
      link="S_link" />
    <axis
      xyz="1 0 0" />
    <limit
      lower="-3"
      upper="-0.5"
      effort="1000"
      velocity="0.5" />
  </joint>
  <gazebo>
    <plugin filename="libgazebo_ros_diff_drive.so" name="differential_drive_controller">
      <alwaysOn>true</alwaysOn>
      <updateRate>20</updateRate>
      <leftJoint>L_joint</leftJoint>
      <rightJoint>R_joint</rightJoint>
      <wheelSeparation>0.350</wheelSeparation>
      <wheelDiameter>0.2</wheelDiameter>
      <torque>100</torque>
      <commandTopic>cmd_vel</commandTopic>
      <odometryTopic>odom</odometryTopic>
      <odometryFrame>odom</odometryFrame>
      <robotBaseFrame>base_link</robotBaseFrame>
    </plugin>
  </gazebo>

</robot>
