<?xml version="1.0" encoding="utf-8"?>
<!-- This URDF was automatically created by SolidWorks to URDF Exporter! Originally created by Stephen Brawner (brawner@gmail.com) 
     Commit Version: 1.6.0-1-g15f4949  Build Version: 1.6.7594.29634
     For more information, please see http://wiki.ros.org/sw_urdf_exporter -->
<robot
  name="box_robot_1">
  <link
    name="base_link">
    <inertial>
      <origin
        xyz="-0.12079 0.15582 -3.351E-16"
        rpy="0 0 0" />
      <mass
        value="8" />
      <inertia
        ixx="0.20526"
        ixy="0.00027898"
        ixz="-1.159E-17"
        iyy="0.21001"
        iyz="1.1924E-17"
        izz="0.16522" />
    </inertial>
    <visual>
      <origin
        xyz="0 0 0"
        rpy="0 0 0" />
      <geometry>
        <mesh
          filename="package://box_robot_1/meshes/base_link.STL" />
      </geometry>
      <material
        name="">
        <color
          rgba="0.79216 0.81961 0.93333 1" />
      </material>
    </visual>
    <collision>
      <origin
        xyz="0 0 0"
        rpy="0 0 0" />
      <geometry>
        <mesh
          filename="package://box_robot_1/meshes/base_link.STL" />
      </geometry>
    </collision>
  </link>
  <link
    name="castor_link">
    <inertial>
      <origin
        xyz="7.6328E-17 6.9389E-18 0"
        rpy="0 0 0" />
      <mass
        value="1" />
      <inertia
        ixx="4.0715E-05"
        ixy="0"
        ixz="-4.2352E-22"
        iyy="4.0715E-05"
        iyz="-6.3527E-22"
        izz="4.0715E-05" />
    </inertial>
    <visual>
      <origin
        xyz="0 0 0"
        rpy="0 0 0" />
      <geometry>
        <mesh
          filename="package://box_robot_1/meshes/castor_link.STL" />
      </geometry>
      <material
        name="">
        <color
          rgba="0.79216 0.81961 0.93333 1" />
      </material>
    </visual>
    <collision>
      <origin
        xyz="0 0 0"
        rpy="0 0 0" />
      <geometry>
        <mesh
          filename="package://box_robot_1/meshes/castor_link.STL" />
      </geometry>
    </collision>
  </link>
  <joint
    name="castor_joint"
    type="continuous">
    <origin
      xyz="-0.16 0 0"
      rpy="1.7421 0.25246 -1.6942" />
    <parent
      link="base_link" />
    <child
      link="castor_link" />
    <axis
      xyz="0 0 1" />
    <dynamics
      damping="0"
      friction="0" />
  </joint>
  <link
    name="right_link">
    <inertial>
      <origin
        xyz="0 0 0.01"
        rpy="0 0 0" />
      <mass
        value="4" />
      <inertia
        ixx="0.00052803"
        ixy="0"
        ixz="1.9565E-20"
        iyy="0.00052803"
        iyz="-9.7809E-20"
        izz="0.0010359" />
    </inertial>
    <visual>
      <origin
        xyz="0 0 0"
        rpy="0 0 0" />
      <geometry>
        <mesh
          filename="package://box_robot_1/meshes/right_link.STL" />
      </geometry>
      <material
        name="">
        <color
          rgba="0.79216 0.81961 0.93333 1" />
      </material>
    </visual>
    <collision>
      <origin
        xyz="0 0 0"
        rpy="0 0 0" />
      <geometry>
        <mesh
          filename="package://box_robot_1/meshes/right_link.STL" />
      </geometry>
    </collision>
  </link>
  <joint
    name="right_joint"
    type="continuous">
    <origin
      xyz="0.12 -0.165 0.05"
      rpy="1.5708 0.0081643 0" />
    <parent
      link="base_link" />
    <child
      link="right_link" />
    <axis
      xyz="0 0 1" />
  </joint>
  <link
    name="left_link">
    <inertial>
      <origin
        xyz="-6.9389E-17 -4.1633E-17 -0.34"
        rpy="0 0 0" />
      <mass
        value="4" />
      <inertia
        ixx="0.00052803"
        ixy="4.7434E-20"
        ixz="1.1116E-20"
        iyy="0.00052803"
        iyz="-9.6357E-20"
        izz="0.0010359" />
    </inertial>
    <visual>
      <origin
        xyz="0 0 0"
        rpy="0 0 0" />
      <geometry>
        <mesh
          filename="package://box_robot_1/meshes/left_link.STL" />
      </geometry>
      <material
        name="">
        <color
          rgba="0.79216 0.81961 0.93333 1" />
      </material>
    </visual>
    <collision>
      <origin
        xyz="0 0 0"
        rpy="0 0 0" />
      <geometry>
        <mesh
          filename="package://box_robot_1/meshes/left_link.STL" />
      </geometry>
    </collision>
  </link>
  <joint
    name="left_joint"
    type="continuous">
    <origin
      xyz="0.12 -0.165 0.05"
      rpy="1.5708 0.054175 0" />
    <parent
      link="base_link" />
    <child
      link="left_link" />
    <axis
      xyz="0 0 1" />
  </joint>
  <link
    name="slider_link">
    <inertial>
      <origin
        xyz="0.155 -0.16031 -0.005"
        rpy="0 0 0" />
      <mass
        value="0.994" />
      <inertia
        ixx="0.0085213"
        ixy="-3.0161E-18"
        ixz="-6.0638E-19"
        iyy="0.0080038"
        iyz="8.6553E-19"
        izz="0.016509" />
    </inertial>
    <visual>
      <origin
        xyz="0 0 0"
        rpy="0 0 0" />
      <geometry>
        <mesh
          filename="package://box_robot_1/meshes/slider_link.STL" />
      </geometry>
      <material
        name="">
        <color
          rgba="0.79216 0.81961 0.93333 1" />
      </material>
    </visual>
    <collision>
      <origin
        xyz="0 0 0"
        rpy="0 0 0" />
      <geometry>
        <mesh
          filename="package://box_robot_1/meshes/slider_link.STL" />
      </geometry>
    </collision>
  </link>
  <joint
    name="slider_joint"
    type="prismatic">
    <origin
      xyz="0.2 0.155 0"
      rpy="-1.5708 0 -1.5708" />
    <parent
      link="base_link" />
    <child
      link="slider_link" />
    <axis
      xyz="0 1 0" />
    <limit
      lower="-0.3"
      upper="0"
      effort="1000"
      velocity="0.5" />
    <dynamics
      damping="0"
      friction="0" />
  </joint>
  <gazebo>
    <plugin filename="libgazebo_ros_diff_drive.so" name="differential_drive_controller">
      <alwaysOn>true</alwaysOn>
      <updateRate>20</updateRate>
      <leftJoint>left_joint</leftJoint>
      <rightJoint>right_joint</rightJoint>
      <wheelSeparation>0.330</wheelSeparation>
      <wheelDiameter>0.16</wheelDiameter>
      <torque>8</torque>
      <commandTopic>cmd_vel</commandTopic>
      <odometryTopic>odom</odometryTopic>
      <odometryFrame>odom</odometryFrame>
      <robotBaseFrame>base_link</robotBaseFrame>
    </plugin>
  </gazebo>
</robot>
