<?xml version="1.0" encoding="utf-8"?>
<!-- This URDF was automatically created by SolidWorks to URDF Exporter! Originally created by Stephen Brawner (brawner@gmail.com) 
     Commit Version: 1.6.0-1-g15f4949  Build Version: 1.6.7594.29634
     For more information, please see http://wiki.ros.org/sw_urdf_exporter -->
<robot
  name="robot_13">
  <link
    name="base_link">
    <inertial>
      <origin
        xyz="0.014544 0.036582 1.6161E-17"
        rpy="0 0 0" />
      <mass
        value="5" />
      <inertia
        ixx="0.10203"
        ixy="0.004034"
        ixz="1.129E-17"
        iyy="0.23912"
        iyz="8.2254E-18"
        izz="0.15152" />
    </inertial>
    <visual>
      <origin
        xyz="0 0 0"
        rpy="0 0 0" />
      <geometry>
        <mesh
          filename="package://robot_13/meshes/base_link.STL" />
      </geometry>
      <material
        name="">
        <color
          rgba="0.79216 0.81961 0.93333 1" />
      </material>
    </visual>
    <collision>
      <origin
        xyz="0 0 0"
        rpy="0 0 0" />
      <geometry>
        <mesh
          filename="package://robot_13/meshes/base_link.STL" />
      </geometry>
    </collision>
  </link>
  <link
    name="L_link">
    <inertial>
      <origin
        xyz="0 0 -0.01125"
        rpy="0 0 0" />
      <mass
        value="0.69095" />
      <inertia
        ixx="0.0017954"
        ixy="1.963E-35"
        ixz="1.0164E-20"
        iyy="0.0017954"
        iyz="1.3775E-36"
        izz="0.0035325" />
    </inertial>
    <visual>
      <origin
        xyz="0 0 0"
        rpy="0 0 0" />
      <geometry>
        <mesh
          filename="package://robot_13/meshes/L_link.STL" />
      </geometry>
      <material
        name="">
        <color
          rgba="0.79216 0.81961 0.93333 1" />
      </material>
    </visual>
    <collision>
      <origin
        xyz="0 0 0"
        rpy="0 0 0" />
      <geometry>
        <mesh
          filename="package://robot_13/meshes/L_link.STL" />
      </geometry>
    </collision>
  </link>
  <joint
    name="L_joint"
    type="continuous">
    <origin
      xyz="-0.13201 0.1775 0.04"
      rpy="1.5708 0 0" />
    <parent
      link="base_link" />
    <child
      link="L_link" />
    <axis
      xyz="0 0 1" />
  </joint>
  <link
    name="R_link">
    <inertial>
      <origin
        xyz="2.7756E-17 0 0.01125"
        rpy="0 0 0" />
      <mass
        value="0.69095" />
      <inertia
        ixx="0.0017954"
        ixy="1.963E-35"
        ixz="1.0164E-20"
        iyy="0.0017954"
        iyz="1.3775E-36"
        izz="0.0035325" />
    </inertial>
    <visual>
      <origin
        xyz="0 0 0"
        rpy="0 0 0" />
      <geometry>
        <mesh
          filename="package://robot_13/meshes/R_link.STL" />
      </geometry>
      <material
        name="">
        <color
          rgba="0.79216 0.81961 0.93333 1" />
      </material>
    </visual>
    <collision>
      <origin
        xyz="0 0 0"
        rpy="0 0 0" />
      <geometry>
        <mesh
          filename="package://robot_13/meshes/R_link.STL" />
      </geometry>
    </collision>
  </link>
  <joint
    name="R_joint"
    type="continuous">
    <origin
      xyz="-0.13201 -0.1775 0.04"
      rpy="1.5708 0 0" />
    <parent
      link="base_link" />
    <child
      link="R_link" />
    <axis
      xyz="0 0 1" />
  </joint>
</robot>