<?xml version="1.0" encoding="utf-8"?>
<!-- This URDF was automatically created by SolidWorks to URDF Exporter! Originally created by Stephen Brawner (brawner@gmail.com) 
     Commit Version: 1.6.0-1-g15f4949  Build Version: 1.6.7594.29634
     For more information, please see http://wiki.ros.org/sw_urdf_exporter -->
<robot
  name="robot_15">
  <link
    name="base_link">
    <inertial>
      <origin
        xyz="0.014544 6.774E-16 0.036582"
        rpy="0 0 0" />
      <mass
        value="5" />
      <inertia
        ixx="0.10203"
        ixy="-7.7327E-18"
        ixz="0.004034"
        iyy="0.15152"
        iyz="-2.6364E-18"
        izz="0.23912" />
    </inertial>
    <visual>
      <origin
        xyz="0 0 0"
        rpy="0 0 0" />
      <geometry>
        <mesh
          filename="package://robot_15/meshes/base_link.STL" />
      </geometry>
      <material
        name="">
        <color
          rgba="0.79216 0.81961 0.93333 1" />
      </material>
    </visual>
    <collision>
      <origin
        xyz="0 0 0"
        rpy="0 0 0" />
      <geometry>
        <mesh
          filename="package://robot_15/meshes/base_link.STL" />
      </geometry>
    </collision>
  </link>
  <link
    name="R_Link">
    <inertial>
      <origin
        xyz="0 0 0.01125"
        rpy="0 0 0" />
      <mass
        value="1" />
      <inertia
        ixx="0.0017954"
        ixy="1.9729E-35"
        ixz="3.1782E-19"
        iyy="0.0017954"
        iyz="-6.1132E-36"
        izz="0.0035325" />
    </inertial>
    <visual>
      <origin
        xyz="0 0 0"
        rpy="0 0 0" />
      <geometry>
        <mesh
          filename="package://robot_15/meshes/R_Link.STL" />
      </geometry>
      <material
        name="">
        <color
          rgba="0.79216 0.81961 0.93333 1" />
      </material>
    </visual>
    <collision>
      <origin
        xyz="0 0 0"
        rpy="0 0 0" />
      <geometry>
        <mesh
          filename="package://robot_15/meshes/R_Link.STL" />
      </geometry>
    </collision>
  </link>
  <joint
    name="R_Joint"
    type="continuous">
    <origin
      xyz="-0.13201 -0.04 -0.1775"
      rpy="3.1416 0 0" />
    <parent
      link="base_link" />
    <child
      link="R_Link" />
    <axis
      xyz="0 0 1" />
  </joint>
  <link
    name="L_Link">
    <inertial>
      <origin
        xyz="0 0 -0.01125"
        rpy="0 0 0" />
      <mass
        value="1" />
      <inertia
        ixx="0.0017954"
        ixy="1.9729E-35"
        ixz="3.1782E-19"
        iyy="0.0017954"
        iyz="-6.325E-36"
        izz="0.0035325" />
    </inertial>
    <visual>
      <origin
        xyz="0 0 0"
        rpy="0 0 0" />
      <geometry>
        <mesh
          filename="package://robot_15/meshes/L_Link.STL" />
      </geometry>
      <material
        name="">
        <color
          rgba="0.79216 0.81961 0.93333 1" />
      </material>
    </visual>
    <collision>
      <origin
        xyz="0 0 0"
        rpy="0 0 0" />
      <geometry>
        <mesh
          filename="package://robot_15/meshes/L_Link.STL" />
      </geometry>
    </collision>
  </link>
  <joint
    name="L_Joint"
    type="continuous">
    <origin
      xyz="-0.13201 -0.04 0.1775"
      rpy="3.1416 0 0" />
    <parent
      link="base_link" />
    <child
      link="L_Link" />
    <axis
      xyz="0 0 1" />
  </joint>
  <link
    name="G_Link">
    <inertial>
      <origin
        xyz="0.0016926 -0.1525 0.062677"
        rpy="0 0 0" />
      <mass
        value="0.5" />
      <inertia
        ixx="0.0033211"
        ixy="-1.3413E-19"
        ixz="1.8332E-05"
        iyy="0.00038553"
        iyz="3.0558E-19"
        izz="0.0030666" />
    </inertial>
    <visual>
      <origin
        xyz="0 0 0"
        rpy="0 0 0" />
      <geometry>
        <mesh
          filename="package://robot_15/meshes/G_Link.STL" />
      </geometry>
      <material
        name="">
        <color
          rgba="0.79216 0.81961 0.93333 1" />
      </material>
    </visual>
    <collision>
      <origin
        xyz="0 0 0"
        rpy="0 0 0" />
      <geometry>
        <mesh
          filename="package://robot_15/meshes/G_Link.STL" />
      </geometry>
    </collision>
  </link>
  <joint
    name="G_Joint"
    type="fixed">
    <origin
      xyz="0.229855170628252 0.05 0.1525"
      rpy="1.5707963267949 0 0" />
    <parent
      link="base_link" />
    <child
      link="G_Link" />
    <axis
      xyz="0 0 0" />
  </joint>
  <link
    name="Slider_Link">
    <inertial>
      <origin
        xyz="0.1525 0.19953 -0.048118"
        rpy="0 0 0" />
      <mass
        value="0.5" />
      <inertia
        ixx="0.0046159"
        ixy="8.7099E-18"
        ixz="-5.287E-20"
        iyy="0.0098749"
        iyz="0.0001874"
        izz="0.013164" />
    </inertial>
    <visual>
      <origin
        xyz="0 0 0"
        rpy="0 0 0" />
      <geometry>
        <mesh
          filename="package://robot_15/meshes/Slider_Link.STL" />
      </geometry>
      <material
        name="">
        <color
          rgba="0.79216 0.81961 0.93333 1" />
      </material>
    </visual>
    <collision>
      <origin
        xyz="0 0 0"
        rpy="0 0 0" />
      <geometry>
        <mesh
          filename="package://robot_15/meshes/Slider_Link.STL" />
      </geometry>
    </collision>
  </link>
  <joint
    name="Slider_Joint"
    type="revolute">
    <origin
      xyz="0.04 0 0.11"
      rpy="3.1355 0 -1.5708" />
    <parent
      link="G_Link" />
    <child
      link="Slider_Link" />
    <axis
      xyz="1 0 0" />
    <limit
      lower="-3"
      upper="-0.5"
      effort="1000"
      velocity="0.5" />
  </joint>
  <link
    name="laser_Link">
    <inertial>
      <origin
        xyz="0.025 -0.025 0.049823"
        rpy="0 0 0" />
      <mass
        value="0.2" />
      <inertia
        ixx="0.00025821"
        ixy="-1.4056E-20"
        ixz="1.9287E-20"
        iyy="0.00025842"
        iyz="7.5508E-22"
        izz="0.00010396" />
    </inertial>
    <visual>
      <origin
        xyz="0 0 0"
        rpy="0 0 0" />
      <geometry>
        <mesh
          filename="package://robot_15/meshes/laser_Link.STL" />
      </geometry>
      <material
        name="">
        <color
          rgba="0.79216 0.81961 0.93333 1" />
      </material>
    </visual>
    <collision>
      <origin
        xyz="0 0 0"
        rpy="0 0 0" />
      <geometry>
        <mesh
          filename="package://robot_15/meshes/laser_Link.STL" />
      </geometry>
    </collision>
  </link>
  <joint
    name="laser_Joint"
    type="fixed">
    <origin
      xyz="0.18485 -0.08 0.025"
      rpy="1.5708 1.5708 0" />
    <parent
      link="base_link" />
    <child
      link="laser_Link" />
    <axis
      xyz="0 0 0" />
  </joint>
  <link
    name="Camera_Link">
    <inertial>
      <origin
        xyz="-0.0004896 1.1762E-08 0.037068"
        rpy="0 0 0" />
      <mass
        value="0.2" />
      <inertia
        ixx="5.2948E-05"
        ixy="-1.0409E-10"
        ixz="5.7682E-07"
        iyy="5.2324E-05"
        iyz="3.5273E-12"
        izz="1.8086E-05" />
    </inertial>
    <visual>
      <origin
        xyz="0 0 0"
        rpy="0 0 0" />
      <geometry>
        <mesh
          filename="package://robot_15/meshes/Camera_Link.STL" />
      </geometry>
      <material
        name="">
        <color
          rgba="0.79216 0.81961 0.93333 1" />
      </material>
    </visual>
    <collision>
      <origin
        xyz="0 0 0"
        rpy="0 0 0" />
      <geometry>
       <box size = "0.1 0.1 0.1" />
      </geometry>
    </collision>
  </link>
  <joint
    name="Camera_Joint"
    type="fixed">
    <origin
      xyz="0.025 -0.025 0.1"
      rpy="0 0 1.5708" />
    <parent
      link="laser_Link" />
    <child
      link="Camera_Link" />
    <axis
      xyz="0 0 0" />
  </joint>
  <gazebo>
    <plugin filename="libgazebo_ros_diff_drive.so" name="differential_drive_controller">
      <alwaysOn>true</alwaysOn>
      <updateRate>20</updateRate>
      <leftJoint>L_Joint</leftJoint>
      <rightJoint>R_Joint</rightJoint>
      <wheelSeparation>0.35</wheelSeparation>
      <wheelDiameter>0.2</wheelDiameter>
      <torque>0.1</torque>
      <commandTopic>cmd_vel</commandTopic>
      <odometryTopic>odom</odometryTopic>
      <odometryFrame>odom</odometryFrame>
      <robotBaseFrame>base_link</robotBaseFrame>
    </plugin>
  </gazebo>

  <gazebo reference="laser_Link">
    <sensor type="ray" name="head_hokuyo_sensor">
      <pose>0 0 0 0 0 0</pose>
      <visualize>false</visualize>
      <update_rate>20</update_rate>
      <ray>
        <scan>
          <horizontal>
            <samples>720</samples>
            <resolution>1</resolution>
            <min_angle>-1.570796</min_angle>
            <max_angle>1.570796</max_angle>
          </horizontal>
        </scan>
        <range>
          <min>0.10</min>
          <max>10.0</max>
          <resolution>0.01</resolution>
        </range>
        <noise>
          <type>gaussian</type>
          <mean>0.0</mean>
          <stddev>0.01</stddev>
        </noise>
      </ray>
      <plugin name="gazebo_ros_head_hokuyo_controller" filename="libgazebo_ros_laser.so">
        <topicName>/robot/laser/scan</topicName>
        <frameName>Sensor_Laser</frameName>
      </plugin>
    </sensor>
  </gazebo>

  <gazebo reference="Camera_Link">
    <sensor type="camera" name="camera1">
      <update_rate>30.0</update_rate>
      <camera name="head">
        <horizontal_fov>1.3962634</horizontal_fov>
        <image>
          <width>800</width>
          <height>800</height>
          <format>R8G8B8</format>
        </image>
        <clip>
          <near>0.02</near>
          <far>300</far>
        </clip>
        <noise>
          <type>gaussian</type>
          <!-- Noise is sampled independently per pixel on each frame.
               That pixel's noise value is added to each of its color
               channels, which at that point lie in the range [0,1]. -->
          <mean>0.0</mean>
          <stddev>0.007</stddev>
        </noise>
      </camera>
      <plugin name="camera_controller" filename="libgazebo_ros_camera.so">
        <alwaysOn>true</alwaysOn>
        <updateRate>0.0</updateRate>
        <cameraName>robot/camera1</cameraName>
        <imageTopicName>image_raw</imageTopicName>
        <cameraInfoTopicName>camera_info</cameraInfoTopicName>
        <frameName>camera_link</frameName>
        <hackBaseline>0.07</hackBaseline>
        <distortionK1>0.0</distortionK1>
        <distortionK2>0.0</distortionK2>
        <distortionK3>0.0</distortionK3>
        <distortionT1>0.0</distortionT1>
        <distortionT2>0.0</distortionT2>
      </plugin>
    </sensor>
  </gazebo>

</robot>
