<?xml version="1.0" encoding="utf-8"?>
<!-- This URDF was automatically created by SolidWorks to URDF Exporter! Originally created by Stephen Brawner (brawner@gmail.com) 
     Commit Version: 1.6.0-1-g15f4949  Build Version: 1.6.7594.29634
     For more information, please see http://wiki.ros.org/sw_urdf_exporter -->
<robot
  name="robot_16">
  <link
    name="base_link">
    <inertial>
      <origin
        xyz="0.014544 -1.3896E-17 0.036582"
        rpy="0 0 0" />
      <mass
        value="5" />
      <inertia
        ixx="0.10203"
        ixy="-1.0838E-17"
        ixz="0.004034"
        iyy="0.15152"
        iyz="-3.2157E-18"
        izz="0.23912" />
    </inertial>
    <visual>
      <origin
        xyz="0 0 0"
        rpy="0 0 0" />
      <geometry>
        <mesh
          filename="package://robot_16/meshes/base_link.STL" />
      </geometry>
      <material
        name="">
        <color
          rgba="0.79216 0.81961 0.93333 1" />
      </material>
    </visual>
    <collision>
      <origin
        xyz="0 0 0"
        rpy="0 0 0" />
      <geometry>
        <mesh
          filename="package://robot_16/meshes/base_link.STL" />
      </geometry>
    </collision>
  </link>
  <link
    name="L_link">
    <inertial>
      <origin
        xyz="0 0 -0.01125"
        rpy="0 0 0" />
      <mass
        value="0.69095" />
      <inertia
        ixx="0.0017954"
        ixy="1.963E-35"
        ixz="1.0164E-20"
        iyy="0.0017954"
        iyz="1.3775E-36"
        izz="0.0035325" />
    </inertial>
    <visual>
      <origin
        xyz="0 0 0"
        rpy="0 0 0" />
      <geometry>
        <mesh
          filename="package://robot_16/meshes/L_link.STL" />
      </geometry>
      <material
        name="">
        <color
          rgba="0.79216 0.81961 0.93333 1" />
      </material>
    </visual>
    <collision>
      <origin
        xyz="0 0 0"
        rpy="0 0 0" />
      <geometry>
        <mesh
          filename="package://robot_16/meshes/L_link.STL" />
      </geometry>
    </collision>
  </link>
  <joint
    name="L_joint"
    type="continuous">
    <origin
      xyz="-0.13201 0.1775 0.04"
      rpy="1.5708 0 0" />
    <parent
      link="base_link" />
    <child
      link="L_link" />
    <axis
      xyz="0 0 1" />
  </joint>
  <link
    name="R_link">
    <inertial>
      <origin
        xyz="2.7756E-17 0 0.01125"
        rpy="0 0 0" />
      <mass
        value="0.69095" />
      <inertia
        ixx="0.0017954"
        ixy="1.963E-35"
        ixz="1.0164E-20"
        iyy="0.0017954"
        iyz="1.3775E-36"
        izz="0.0035325" />
    </inertial>
    <visual>
      <origin
        xyz="0 0 0"
        rpy="0 0 0" />
      <geometry>
        <mesh
          filename="package://robot_16/meshes/R_link.STL" />
      </geometry>
      <material
        name="">
        <color
          rgba="0.79216 0.81961 0.93333 1" />
      </material>
    </visual>
    <collision>
      <origin
        xyz="0 0 0"
        rpy="0 0 0" />
      <geometry>
        <mesh
          filename="package://robot_16/meshes/R_link.STL" />
      </geometry>
    </collision>
  </link>
  <joint
    name="R_joint"
    type="continuous">
    <origin
      xyz="-0.13201 -0.1775 0.04"
      rpy="1.5708 0 0" />
    <parent
      link="base_link" />
    <child
      link="R_link" />
    <axis
      xyz="0 0 1" />
  </joint>
  <link
    name="Gripper_link">
    <inertial>
      <origin
        xyz="0.0016926 -0.1525 0.062677"
        rpy="0 0 0" />
      <mass
        value="0.27354" />
      <inertia
        ixx="0.0033211"
        ixy="7.056E-19"
        ixz="1.8332E-05"
        iyy="0.00038553"
        iyz="-5.0703E-19"
        izz="0.0030666" />
    </inertial>
    <visual>
      <origin
        xyz="0 0 0"
        rpy="0 0 0" />
      <geometry>
        <mesh
          filename="package://robot_16/meshes/Gripper_link.STL" />
      </geometry>
      <material
        name="">
        <color
          rgba="0.79216 0.81961 0.93333 1" />
      </material>
    </visual>
    <collision>
      <origin
        xyz="0 0 0"
        rpy="0 0 0" />
      <geometry>
        <mesh
          filename="package://robot_16/meshes/Gripper_link.STL" />
      </geometry>
    </collision>
  </link>
  <joint
    name="Gripper_joint"
    type="fixed">
    <origin
      xyz="0.22986 0.1525 -0.05"
      rpy="0 0 0" />
    <parent
      link="base_link" />
    <child
      link="Gripper_link" />
    <axis
      xyz="0 0 0" />
  </joint>
  <link
    name="S_link">
    <inertial>
      <origin
        xyz="0.1525 0.19739 -0.056227"
        rpy="0 0 0" />
      <mass
        value="0.56165" />
      <inertia
        ixx="0.0046159"
        ixy="1.7457E-17"
        ixz="-1.5799E-18"
        iyy="0.0098957"
        iyz="0.00032101"
        izz="0.013144" />
    </inertial>
    <visual>
      <origin
        xyz="0 0 0"
        rpy="0 0 0" />
      <geometry>
        <mesh
          filename="package://robot_16/meshes/S_link.STL" />
      </geometry>
      <material
        name="">
        <color
          rgba="0.79216 0.81961 0.93333 1" />
      </material>
    </visual>
    <collision>
      <origin
        xyz="0 0 0"
        rpy="0 0 0" />
      <geometry>
        <mesh
          filename="package://robot_16/meshes/S_link.STL" />
      </geometry>
    </collision>
  </link>
  <joint
    name="Slider_joint"
    type="revolute">
    <origin
      xyz="0.04 0 0.11"
      rpy="-3.1212 0 -1.5708" />
    <parent
      link="Gripper_link" />
    <child
      link="S_link" />
    <axis
      xyz="1 0 0" />
    <limit
      lower="-3"
      upper="-0.5"
      effort="1000"
      velocity="0.5" />
  </joint>
</robot>