<<<<<<< HEAD
<?xml version="1.0" encoding="utf-8"?>
<!-- This URDF was automatically created by SolidWorks to URDF Exporter! Originally created by Stephen Brawner (brawner@gmail.com) 
     Commit Version: 1.6.0-1-g15f4949  Build Version: 1.6.7594.29634
     For more information, please see http://wiki.ros.org/sw_urdf_exporter -->
<robot
  name="robot_16">
  <link
    name="base_link">
    <inertial>
      <origin
        xyz="0.014544 -1.3896E-17 0.036582"
        rpy="0 0 0" />
      <mass
        value="5" />
      <inertia
        ixx="0.10203"
        ixy="-1.0838E-17"
        ixz="0.004034"
        iyy="0.15152"
        iyz="-3.2157E-18"
        izz="0.23912" />
    </inertial>
    <visual>
      <origin
        xyz="0 0 0"
        rpy="0 0 0" />
      <geometry>
        <mesh
          filename="package://robot_16/meshes/base_link.STL" />
      </geometry>
      <material
        name="">
        <color
          rgba="0.79216 0.81961 0.93333 1" />
      </material>
    </visual>
    <collision>
      <origin
        xyz="0 0 0"
        rpy="0 0 0" />
      <geometry>
        <mesh
          filename="package://robot_16/meshes/base_link.STL" />
      </geometry>
    </collision>
  </link>
  <link
    name="L_link">
    <inertial>
      <origin
        xyz="0 0 -0.01125"
        rpy="0 0 0" />
      <mass
        value="0.69095" />
      <inertia
        ixx="0.0017954"
        ixy="1.963E-35"
        ixz="1.0164E-20"
        iyy="0.0017954"
        iyz="1.3775E-36"
        izz="0.0035325" />
    </inertial>
    <visual>
      <origin
        xyz="0 0 0"
        rpy="0 0 0" />
      <geometry>
        <mesh
          filename="package://robot_16/meshes/L_link.STL" />
      </geometry>
      <material
        name="">
        <color
          rgba="0.79216 0.81961 0.93333 1" />
      </material>
    </visual>
    <collision>
      <origin
        xyz="0 0 0"
        rpy="0 0 0" />
      <geometry>
        <mesh
          filename="package://robot_16/meshes/L_link.STL" />
      </geometry>
    </collision>
  </link>
  <joint
    name="L_joint"
    type="continuous">
    <origin
      xyz="-0.13201 0.1775 0.04"
      rpy="1.5708 0 0" />
    <parent
      link="base_link" />
    <child
      link="L_link" />
    <axis
      xyz="0 0 1" />
  </joint>
  <link
    name="R_link">
    <inertial>
      <origin
        xyz="2.7756E-17 0 0.01125"
        rpy="0 0 0" />
      <mass
        value="0.69095" />
      <inertia
        ixx="0.0017954"
        ixy="1.963E-35"
        ixz="1.0164E-20"
        iyy="0.0017954"
        iyz="1.3775E-36"
        izz="0.0035325" />
    </inertial>
    <visual>
      <origin
        xyz="0 0 0"
        rpy="0 0 0" />
      <geometry>
        <mesh
          filename="package://robot_16/meshes/R_link.STL" />
      </geometry>
      <material
        name="">
        <color
          rgba="0.79216 0.81961 0.93333 1" />
      </material>
    </visual>
    <collision>
      <origin
        xyz="0 0 0"
        rpy="0 0 0" />
      <geometry>
        <mesh
          filename="package://robot_16/meshes/R_link.STL" />
      </geometry>
    </collision>
  </link>
  <joint
    name="R_joint"
    type="continuous">
    <origin
      xyz="-0.13201 -0.1775 0.04"
      rpy="1.5708 0 0" />
    <parent
      link="base_link" />
    <child
      link="R_link" />
    <axis
      xyz="0 0 1" />
  </joint>
  <link
    name="Gripper_link">
    <inertial>
      <origin
        xyz="0.0016926 -0.1525 0.062677"
        rpy="0 0 0" />
      <mass
        value="0.27354" />
      <inertia
        ixx="0.0033211"
        ixy="7.056E-19"
        ixz="1.8332E-05"
        iyy="0.00038553"
        iyz="-5.0703E-19"
        izz="0.0030666" />
    </inertial>
    <visual>
      <origin
        xyz="0 0 0"
        rpy="0 0 0" />
      <geometry>
        <mesh
          filename="package://robot_16/meshes/Gripper_link.STL" />
      </geometry>
      <material
        name="">
        <color
          rgba="0.79216 0.81961 0.93333 1" />
      </material>
    </visual>
    <collision>
      <origin
        xyz="0 0 0"
        rpy="0 0 0" />
      <geometry>
        <mesh
          filename="package://robot_16/meshes/Gripper_link.STL" />
      </geometry>
    </collision>
  </link>
  <joint
    name="Gripper_joint"
    type="fixed">
    <origin
      xyz="0.22986 0.1525 -0.05"
      rpy="0 0 0" />
    <parent
      link="base_link" />
    <child
      link="Gripper_link" />
    <axis
      xyz="0 0 0" />
  </joint>
  <link
    name="S_link">
    <inertial>
      <origin
        xyz="0.1525 0.19739 -0.056227"
        rpy="0 0 0" />
      <mass
        value="0.56165" />
      <inertia
        ixx="0.0046159"
        ixy="1.7457E-17"
        ixz="-1.5799E-18"
        iyy="0.0098957"
        iyz="0.00032101"
        izz="0.013144" />
    </inertial>
    <visual>
      <origin
        xyz="0 0 0"
        rpy="0 0 0" />
      <geometry>
        <mesh
          filename="package://robot_16/meshes/S_link.STL" />
      </geometry>
      <material
        name="">
        <color
          rgba="0.79216 0.81961 0.93333 1" />
      </material>
    </visual>
    <collision>
      <origin
        xyz="0 0 0"
        rpy="0 0 0" />
      <geometry>
        <mesh
          filename="package://robot_16/meshes/S_link.STL" />
      </geometry>
    </collision>
  </link>
  <joint
    name="Slider_joint"
    type="revolute">
    <origin
      xyz="0.04 0 0.11"
      rpy="-3.1212 0 -1.5708" />
    <parent
      link="Gripper_link" />
    <child
      link="S_link" />
    <axis
      xyz="1 0 0" />
    <limit
      lower="-3"
      upper="-0.5"
      effort="1000"
      velocity="0.5" />
  </joint>
</robot>
=======
<?xml version="1.0" encoding="utf-8"?>
<!-- This URDF was automatically created by SolidWorks to URDF Exporter! Originally created by Stephen Brawner (brawner@gmail.com) 
     Commit Version: 1.6.0-1-g15f4949  Build Version: 1.6.7594.29634
     For more information, please see http://wiki.ros.org/sw_urdf_exporter -->
<robot
  name="robot_16">
  <link
    name="base_link">
    <inertial>
      <origin
        xyz="0.0145441493723993 -1.36020916563464E-17 0.0365817554752582"
        rpy="0 0 0" />
      <mass
        value="10.6285208191334" />
      <inertia
        ixx="0.102028273795723"
        ixy="-1.08532393870512E-17"
        ixz="0.00403401272589497"
        iyy="0.151518571448495"
        iyz="-2.70212659589984E-18"
        izz="0.23911906106474" />
    </inertial>
    <visual>
      <origin
        xyz="0 0 0"
        rpy="0 0 0" />
      <geometry>
        <mesh
          filename="package://robot_16/meshes/base_link.STL" />
      </geometry>
      <material
        name="">
        <color
          rgba="0.792156862745098 0.819607843137255 0.933333333333333 1" />
      </material>
    </visual>
    <collision>
      <origin
        xyz="0 0 0"
        rpy="0 0 0" />
      <geometry>
        <mesh
          filename="package://robot_16/meshes/base_link.STL" />
      </geometry>
    </collision>
  </link>
  <link
    name="L_link">
    <inertial>
      <origin
        xyz="0 0 -0.01125"
        rpy="0 0 0" />
      <mass
        value="0.690954034248905" />
      <inertia
        ixx="0.00179540087336864"
        ixy="1.96300714533835E-35"
        ixz="1.01643953670516E-20"
        iyy="0.00179540087336864"
        iyz="2.20405190779179E-36"
        izz="0.00353250250009753" />
    </inertial>
    <visual>
      <origin
        xyz="0 0 0"
        rpy="0 0 0" />
      <geometry>
        <mesh
          filename="package://robot_16/meshes/L_link.STL" />
      </geometry>
      <material
        name="">
        <color
          rgba="0.792156862745098 0.819607843137255 0.933333333333333 1" />
      </material>
    </visual>
    <collision>
      <origin
        xyz="0 0 0"
        rpy="0 0 0" />
      <geometry>
        <mesh
          filename="package://robot_16/meshes/L_link.STL" />
      </geometry>
    </collision>
  </link>
  <joint
    name="L_joint"
    type="continuous">
    <origin
      xyz="-0.13201 0.1775 0.04"
      rpy="1.5708 0 0" />
    <parent
      link="base_link" />
    <child
      link="L_link" />
    <axis
      xyz="0 0 -1" />
  </joint>
  <link
    name="R_link">
    <inertial>
      <origin
        xyz="2.77555756156289E-17 0 0.01125"
        rpy="0 0 0" />
      <mass
        value="0.690954034248905" />
      <inertia
        ixx="0.00179540087336864"
        ixy="1.96300714533835E-35"
        ixz="1.01643953670516E-20"
        iyy="0.00179540087336864"
        iyz="1.37753244236988E-36"
        izz="0.00353250250009753" />
    </inertial>
    <visual>
      <origin
        xyz="0 0 0"
        rpy="0 0 0" />
      <geometry>
        <mesh
          filename="package://robot_16/meshes/R_link.STL" />
      </geometry>
      <material
        name="">
        <color
          rgba="0.792156862745098 0.819607843137255 0.933333333333333 1" />
      </material>
    </visual>
    <collision>
      <origin
        xyz="0 0 0"
        rpy="0 0 0" />
      <geometry>
        <mesh
          filename="package://robot_16/meshes/R_link.STL" />
      </geometry>
    </collision>
  </link>
  <joint
    name="R_joint"
    type="continuous">
    <origin
      xyz="-0.132007907908432 -0.1775 0.04"
      rpy="1.5707963267949 0 0" />
    <parent
      link="base_link" />
    <child
      link="R_link" />
    <axis
      xyz="0 0 -1" />
  </joint>
  <link
    name="Gripper_link">
    <inertial>
      <origin
        xyz="0.00169258177970372 -0.1525 0.0626773923404718"
        rpy="0 0 0" />
      <mass
        value="0.27354369260617" />
      <inertia
        ixx="0.00332109827650254"
        ixy="6.83188507102723E-19"
        ixz="1.83318469851867E-05"
        iyy="0.000385532675137136"
        iyz="-4.8887290139426E-19"
        izz="0.00306661973981523" />
    </inertial>
    <visual>
      <origin
        xyz="0 0 0"
        rpy="0 0 0" />
      <geometry>
        <mesh
          filename="package://robot_16/meshes/Gripper_link.STL" />
      </geometry>
      <material
        name="">
        <color
          rgba="0.792156862745098 0.819607843137255 0.933333333333333 1" />
      </material>
    </visual>
    <collision>
      <origin
        xyz="0 0 0"
        rpy="0 0 0" />
      <geometry>
        <mesh
          filename="package://robot_16/meshes/Gripper_link.STL" />
      </geometry>
    </collision>
  </link>
  <joint
    name="Gripper_joint"
    type="fixed">
    <origin
      xyz="0.22986 0.1525 -0.05"
      rpy="0 0 0" />
    <parent
      link="base_link" />
    <child
      link="Gripper_link" />
    <axis
      xyz="0 0 0" />
  </joint>
  <link
    name="S_link">
    <inertial>
      <origin
        xyz="0.1525 -0.200722822434886 0.0428489354574837"
        rpy="0 0 0" />
      <mass
        value="0.561654902143577" />
      <inertia
        ixx="0.00461592441893209"
        ixy="-8.73447451863333E-18"
        ixz="1.40439319658268E-18"
        iyy="0.00986729875961306"
        iyz="0.000100571789775732"
        izz="0.0131719741536673" />
    </inertial>
    <visual>
      <origin
        xyz="0 0 0"
        rpy="0 0 0" />
      <geometry>
        <mesh
          filename="package://robot_16/meshes/S_link.STL" />
      </geometry>
      <material
        name="">
        <color
          rgba="0.792156862745098 0.819607843137255 0.933333333333333 1" />
      </material>
    </visual>
    <collision>
      <origin
        xyz="0 0 0"
        rpy="0 0 0" />
      <geometry>
        <mesh
          filename="package://robot_16/meshes/S_link.STL" />
      </geometry>
    </collision>
  </link>
  <joint
    name="Slider_joint"
    type="revolute">
    <origin
      xyz="0.04 0 0.11"
      rpy="-3.1212 0 -1.5708" />
    <parent
      link="Gripper_link" />
    <child
      link="S_link" />
    <axis
      xyz="1 0 0" />
    <limit
      lower="0"
      upper="3"
      effort="1000"
      velocity="0.5" />
  </joint>
  <link
    name="C_Link">
    <inertial>
      <origin
        xyz="0.005 0.0050347 -0.075342"
        rpy="0 0 0" />
      <mass
        value="1" />
      <inertia
        ixx="2.8613E-05"
        ixy="-3.9546E-23"
        ixz="-2.3934E-21"
        iyy="2.8609E-05"
        iyz="3.6416E-08"
        izz="2.5395E-07" />
    </inertial>
    <visual>
      <origin
        xyz="0 0 0"
        rpy="0 0 0" />
      <geometry>
        <box size = "0.01 0.01 0.25" />
      </geometry>
      <material
        name="">
        <color
          rgba="0.79216 0.81961 0.93333 1" />
      </material>
    </visual>
    <collision>
      <origin
        xyz="0 0 0"
        rpy="0 0 0" />
      <geometry>
        <box size = "0.01 0.01 0.25" />
      </geometry>
    </collision>
  </link>
  <joint
    name="C_joint"
    type="fixed">
    <origin
      xyz="-0.16 0 0.21"
      rpy="0 0 0" />
    <parent
      link="base_link" />
    <child
      link="C_Link" />
    <axis
      xyz="0 0 0" />
  </joint>
  <gazebo>
    <plugin filename="libgazebo_ros_diff_drive.so" name="differential_drive_controller">
      <alwaysOn>true</alwaysOn>
      <updateRate>20</updateRate>
      <leftJoint>L_joint</leftJoint>
      <rightJoint>R_joint</rightJoint>
      <wheelSeparation>0.35</wheelSeparation>
      <wheelDiameter>0.2</wheelDiameter>
      <torque>100</torque>
      <commandTopic>cmd_vel</commandTopic>
      <odometryTopic>odom</odometryTopic>
      <odometryFrame>odom</odometryFrame>
      <robotBaseFrame>base_link</robotBaseFrame>
    </plugin>
  </gazebo>
  <gazebo reference="C_Link">
    <sensor type="camera" name="camera1">
      <update_rate>30.0</update_rate>
      <camera name="head">
        <horizontal_fov>1.3962634</horizontal_fov>
        <image>
          <width>800</width>
          <height>800</height>
          <format>R8G8B8</format>
        </image>
        <clip>
          <near>0.02</near>
          <far>300</far>
        </clip>
        <noise>
          <type>gaussian</type>
          <!-- Noise is sampled independently per pixel on each frame.
               That pixel's noise value is added to each of its color
               channels, which at that point lie in the range [0,1]. -->
          <mean>0.0</mean>
          <stddev>0.007</stddev>
        </noise>
      </camera>
      <plugin name="camera_controller" filename="libgazebo_ros_camera.so">
        <alwaysOn>true</alwaysOn>
        <updateRate>0.0</updateRate>
        <cameraName>robot/camera1</cameraName>
        <imageTopicName>image_raw</imageTopicName>
        <cameraInfoTopicName>camera_info</cameraInfoTopicName>
        <frameName>camera_link</frameName>
        <hackBaseline>0.07</hackBaseline>
        <distortionK1>0.0</distortionK1>
        <distortionK2>0.0</distortionK2>
        <distortionK3>0.0</distortionK3>
        <distortionT1>0.0</distortionT1>
        <distortionT2>0.0</distortionT2>
      </plugin>
    </sensor>
  </gazebo>

</robot>
>>>>>>> afd7ac50768724142e39a93e996782eecf41a9fc
