<?xml version="1.0" encoding="utf-8"?>
<!-- This URDF was automatically created by SolidWorks to URDF Exporter! Originally created by Stephen Brawner (brawner@gmail.com) 
     Commit Version: 1.6.0-1-g15f4949  Build Version: 1.6.7594.29634
     For more information, please see http://wiki.ros.org/sw_urdf_exporter -->
<robot
  name="robot_1">
  <link
    name="base_link">
    <inertial>
      <origin
        xyz="0.0030659 -0.039986 -1.2725E-18"
        rpy="0 0 0" />
      <mass
        value="5" />
      <inertia
        ixx="0.099402"
        ixy="0.00070311"
        ixz="-2.0017E-17"
        iyy="0.22181"
        iyz="-7.3082E-18"
        izz="0.13288" />
    </inertial>
    <visual>
      <origin
        xyz="0 0 0"
        rpy="0 0 0" />
      <geometry>
        <mesh
          filename="package://robot_1/meshes/base_link.STL" />
      </geometry>
      <material
        name="">
        <color
          rgba="0.79216 0.81961 0.93333 1" />
      </material>
    </visual>
    <collision>
      <origin
        xyz="0 0 0"
        rpy="0 0 0" />
      <geometry>
        <mesh
          filename="package://robot_1/meshes/base_link.STL" />
      </geometry>
    </collision>
  </link>
  <link
    name="R_Link">
    <inertial>
      <origin
        xyz="0.015916 0 4.8572E-17"
        rpy="0 0 0" />
      <mass
        value="0.5" />
      <inertia
        ixx="0.0030661"
        ixy="2.783E-19"
        ixz="-9.1783E-20"
        iyy="0.0015677"
        iyz="3.6253E-19"
        izz="0.0015677" />
    </inertial>
    <visual>
      <origin
        xyz="0 0 0"
        rpy="0 0 0" />
      <geometry>
        <mesh
          filename="package://robot_1/meshes/R_Link.STL" />
      </geometry>
      <material
        name="">
        <color
          rgba="0.79216 0.81961 0.93333 1" />
      </material>
    </visual>
    <collision>
      <origin
        xyz="0 0 0"
        rpy="0 0 0" />
      <geometry>
        <mesh
          filename="package://robot_1/meshes/R_Link.STL" />
      </geometry>
    </collision>
  </link>
  <joint
    name="Right_Joint"
    type="continuous">
    <origin
      xyz="-0.082008 -0.04 -0.18"
      rpy="1.5832 1.5708 0" />
    <parent
      link="base_link" />
    <child
      link="R_Link" />
    <axis
      xyz="1 0 0" />
  </joint>
  <link
    name="Left_Link">
    <inertial>
      <origin
        xyz="0.37592 -1.3184E-16 0"
        rpy="0 0 0" />
      <mass
        value="0.5" />
      <inertia
        ixx="0.0030661"
        ixy="4.678E-20"
        ixz="-3.5818E-19"
        iyy="0.0015677"
        iyz="2.7105E-19"
        izz="0.0015677" />
    </inertial>
    <visual>
      <origin
        xyz="0 0 0"
        rpy="0 0 0" />
      <geometry>
        <mesh
          filename="package://robot_1/meshes/Left_Link.STL" />
      </geometry>
      <material
        name="">
        <color
          rgba="0.79216 0.81961 0.93333 1" />
      </material>
    </visual>
    <collision>
      <origin
        xyz="0 0 0"
        rpy="0 0 0" />
      <geometry>
        <mesh
          filename="package://robot_1/meshes/Left_Link.STL" />
      </geometry>
    </collision>
  </link>
  <joint
    name="Left_Joint"
    type="continuous">
    <origin
      xyz="-0.082008 -0.04 -0.18"
      rpy="0.13675 -1.5708 0" />
    <parent
      link="base_link" />
    <child
      link="Left_Link" />
    <axis
      xyz="1 0 0" />
  </joint>
  <link
    name="Gripper_Link">
    <inertial>
      <origin
        xyz="-0.00034054 -0.1525 0.029974"
        rpy="0 0 0" />
      <mass
        value="1" />
      <inertia
        ixx="0.0015375"
        ixy="1.9323E-19"
        ixz="1.5842E-07"
        iyy="7.9169E-05"
        iyz="-7.0054E-22"
        izz="0.0015394" />
    </inertial>
    <visual>
      <origin
        xyz="0 0 0"
        rpy="0 0 0" />
      <geometry>
        <mesh
          filename="package://robot_1/meshes/Gripper_Link.STL" />
      </geometry>
      <material
        name="">
        <color
          rgba="0.79216 0.81961 0.93333 1" />
      </material>
    </visual>
    <collision>
      <origin
        xyz="0 0 0"
        rpy="0 0 0" />
      <geometry>
        <mesh
          filename="package://robot_1/meshes/Gripper_Link.STL" />
      </geometry>
    </collision>
  </link>
  <joint
    name="Gripper_Joint"
    type="fixed">
    <origin
      xyz="0.22986 -0.01 0.1525"
      rpy="1.5708 0 0" />
    <parent
      link="base_link" />
    <child
      link="Gripper_Link" />
    <axis
      xyz="0 0 0" />
  </joint>
  <link
    name="Slider_Link">
    <inertial>
      <origin
        xyz="0.1525 0.1949 -0.019552"
        rpy="0 0 0" />
      <mass
        value="1" />
      <inertia
        ixx="0.0022843"
        ixy="5.3543E-18"
        ixz="-6.6132E-19"
        iyy="0.0048941"
        iyz="2.4421E-05"
        izz="0.0070064" />
    </inertial>
    <visual>
      <origin
        xyz="0 0 0"
        rpy="0 0 0" />
      <geometry>
        <mesh
          filename="package://robot_1/meshes/Slider_Link.STL" />
      </geometry>
      <material
        name="">
        <color
          rgba="0.79216 0.81961 0.93333 1" />
      </material>
    </visual>
    <collision>
      <origin
        xyz="0 0 0"
        rpy="0 0 0" />
      <geometry>
        <mesh
          filename="package://robot_1/meshes/Slider_Link.STL" />
      </geometry>
    </collision>
  </link>
  <joint
    name="Slider_Joint"
    type="continuous">
    <origin
      xyz="0.04 0 0.05"
      rpy="3.1133 0 -1.5708" />
    <parent
      link="Gripper_Link" />
    <child
      link="Slider_Link" />
    <axis
      xyz="1 0 0" />
    <limit
      lower="0"
      upper="3.1428"
      effort="0"
      velocity="0" />
  </joint>
</robot>