<?xml version="1.0" encoding="utf-8"?>
<!-- This URDF was automatically created by SolidWorks to URDF Exporter! Originally created by Stephen Brawner (brawner@gmail.com) 
     Commit Version: 1.6.0-1-g15f4949  Build Version: 1.6.7594.29634
     For more information, please see http://wiki.ros.org/sw_urdf_exporter -->
<robot
  name="robot_17">
  <link
    name="base_link">
    <inertial>
      <origin
        xyz="-1.8421E-17 0.047887 -0.026797"
        rpy="0 0 0" />
      <mass
        value="5" />
      <inertia
        ixx="0.19581"
        ixy="1.7576E-18"
        ixz="2.8453E-17"
        iyy="0.29669"
        iyz="0.020407"
        izz="0.13262" />
    </inertial>
    <visual>
      <origin
        xyz="0 0 0"
        rpy="0 0 0" />
      <geometry>
        <mesh
          filename="package://robot_17/meshes/base_link.STL" />
      </geometry>
      <material
        name="">
        <color
          rgba="0.79216 0.81961 0.93333 1" />
      </material>
    </visual>
    <collision>
      <origin
        xyz="0 0 0"
        rpy="0 0 0" />
      <geometry>
        <mesh
          filename="package://robot_17/meshes/base_link.STL" />
      </geometry>
    </collision>
  </link>
  <link
    name="L_link">
    <inertial>
      <origin
        xyz="0 0 0.01125"
        rpy="0 0 0" />
      <mass
        value="0.69095" />
      <inertia
        ixx="0.0017954"
        ixy="2.9845E-33"
        ixz="-1.0164E-20"
        iyy="0.0017954"
        iyz="-5.0572E-22"
        izz="0.0035325" />
    </inertial>
    <visual>
      <origin
        xyz="0 0 0"
        rpy="0 0 0" />
      <geometry>
        <mesh
          filename="package://robot_17/meshes/L_link.STL" />
      </geometry>
      <material
        name="">
        <color
          rgba="0.79216 0.81961 0.93333 1" />
      </material>
    </visual>
    <collision>
      <origin
        xyz="0 0 0"
        rpy="0 0 0" />
      <geometry>
        <mesh
          filename="package://robot_17/meshes/L_link.STL" />
      </geometry>
    </collision>
  </link>
  <joint
    name="L_joint"
    type="continuous">
    <origin
      xyz="0.1775 0.15093 0.04"
      rpy="-1.5708 0 -1.5708" />
    <parent
      link="base_link" />
    <child
      link="L_link" />
    <axis
      xyz="0 0 1" />
  </joint>
  <link
    name="R_link">
    <inertial>
      <origin
        xyz="0 0 0.01125"
        rpy="0 0 0" />
      <mass
        value="0.69095" />
      <inertia
        ixx="0.0017954"
        ixy="-1.3553E-20"
        ixz="-3.3154E-19"
        iyy="0.0017954"
        iyz="2.7118E-20"
        izz="0.0035325" />
    </inertial>
    <visual>
      <origin
        xyz="0 0 0"
        rpy="0 0 0" />
      <geometry>
        <mesh
          filename="package://robot_17/meshes/R_link.STL" />
      </geometry>
      <material
        name="">
        <color
          rgba="0.79216 0.81961 0.93333 1" />
      </material>
    </visual>
    <collision>
      <origin
        xyz="0 0 0"
        rpy="0 0 0" />
      <geometry>
        <mesh
          filename="package://robot_17/meshes/R_link.STL" />
      </geometry>
    </collision>
  </link>
  <joint
    name="R_joint"
    type="continuous">
    <origin
      xyz="-0.1775 0.15093 0.04"
      rpy="-1.5708 0.095053 1.5708" />
    <parent
      link="base_link" />
    <child
      link="R_link" />
    <axis
      xyz="0 0 1" />
  </joint>
  <link
    name="Gripper_link">
    <inertial>
      <origin
        xyz="0.0016471 0.155 -0.062648"
        rpy="0 0 0" />
      <mass
        value="0.27654" />
      <inertia
        ixx="0.003447"
        ixy="-4.3916E-19"
        ixz="-1.8299E-05"
        iyy="0.00038921"
        iyz="6.4802E-19"
        izz="0.003189" />
    </inertial>
    <visual>
      <origin
        xyz="0 0 0"
        rpy="0 0 0" />
      <geometry>
        <mesh
          filename="package://robot_17/meshes/Gripper_link.STL" />
      </geometry>
      <material
        name="">
        <color
          rgba="0.79216 0.81961 0.93333 1" />
      </material>
    </visual>
    <collision>
      <origin
        xyz="0 0 0"
        rpy="0 0 0" />
      <geometry>
        <mesh
          filename="package://robot_17/meshes/Gripper_link.STL" />
      </geometry>
    </collision>
  </link>
  <joint
    name="Gripper_joint"
    type="fixed">
    <origin
      xyz="0.155 -0.21093 -0.05"
      rpy="3.1416 0 -1.5708" />
    <parent
      link="base_link" />
    <child
      link="Gripper_link" />
    <axis
      xyz="0 0 0" />
  </joint>
  <link
    name="S_link">
    <inertial>
      <origin
        xyz="0.155 0.19524 -0.048102"
        rpy="0 0 0" />
      <mass
        value="0.55679" />
      <inertia
        ixx="0.0043155"
        ixy="-2.4988E-19"
        ixz="1.1244E-18"
        iyy="0.0099472"
        iyz="0.00018287"
        izz="0.012948" />
    </inertial>
    <visual>
      <origin
        xyz="0 0 0"
        rpy="0 0 0" />
      <geometry>
        <mesh
          filename="package://robot_17/meshes/S_link.STL" />
      </geometry>
      <material
        name="">
        <color
          rgba="0.79216 0.81961 0.93333 1" />
      </material>
    </visual>
    <collision>
      <origin
        xyz="0 0 0"
        rpy="0 0 0" />
      <geometry>
        <mesh
          filename="package://robot_17/meshes/S_link.STL" />
      </geometry>
    </collision>
  </link>
  <joint
    name="Slider_joint"
    type="revolute">
    <origin
      xyz="0.04 0 -0.11"
      rpy="-0.97212 0 1.5708" />
    <parent
      link="Gripper_link" />
    <child
      link="S_link" />
    <axis
      xyz="1 0 0" />
    <limit
      lower="-3"
      upper="-0.5"
      effort="1000"
      velocity="0.5" />
  </joint>
  <link
    name="C_Link">
    <inertial>
      <origin
        xyz="0.005 -0.0050347 0.075342"
        rpy="0 0 0" />
      <mass
        value="0.015074" />
      <inertia
        ixx="2.8613E-05"
        ixy="4.1046E-24"
        ixz="-1.0348E-21"
        iyy="2.8609E-05"
        iyz="3.6416E-08"
        izz="2.5395E-07" />
    </inertial>
    <visual>
      <origin
        xyz="0 0 0"
        rpy="0 0 0" />
      <geometry>
        <mesh
          filename="package://robot_17/meshes/C_Link.STL" />
      </geometry>
      <material
        name="">
        <color
          rgba="0.79216 0.81961 0.93333 1" />
      </material>
    </visual>
    <collision>
      <origin
        xyz="0 0 0"
        rpy="0 0 0" />
      <geometry>
        <mesh
          filename="package://robot_17/meshes/C_Link.STL" />
      </geometry>
    </collision>
  </link>
  <joint
    name="C_joint"
    type="fixed">
    <origin
      xyz="-0.00500000000000001 0.18093 0.13"
      rpy="0 0 0" />
    <parent
      link="base_link" />
    <child
      link="C_Link" />
    <axis
      xyz="0 0 0" />
  </joint>
  <link
    name="laser_link">
    <inertial>
      <origin
        xyz="0.005 -0.005 0.024861"
        rpy="0 0 0" />
      <mass
        value="0.0049686" />
      <inertia
        ixx="1.0678E-06"
        ixy="8.8775E-24"
        ixz="-5.7315E-24"
        iyy="1.068E-06"
        iyz="-1.1453E-24"
        izz="8.3064E-08" />
    </inertial>
    <visual>
      <origin
        xyz="0 0 0"
        rpy="0 0 0" />
      <geometry>
        <mesh
          filename="package://robot_17/meshes/laser_link.STL" />
      </geometry>
      <material
        name="">
        <color
          rgba="0.79216 0.81961 0.93333 1" />
      </material>
    </visual>
    <collision>
      <origin
        xyz="0 0 0"
        rpy="0 0 0" />
      <geometry>
        <mesh
          filename="package://robot_17/meshes/laser_link.STL" />
      </geometry>
    </collision>
  </link>
  <joint
    name="laser_joint"
    type="fixed">
    <origin
      xyz="0.005 -0.19093 0.08"
      rpy="0 0 3.1416" />
    <parent
      link="base_link" />
    <child
      link="laser_link" />
    <axis
      xyz="0 0 0" />
  </joint>
</robot>