<?xml version="1.0" encoding="utf-8"?>
<!-- This URDF was automatically created by SolidWorks to URDF Exporter! Originally created by Stephen Brawner (brawner@gmail.com) 
     Commit Version: 1.6.0-1-g15f4949  Build Version: 1.6.7594.29634
     For more information, please see http://wiki.ros.org/sw_urdf_exporter -->
<robot
  name="box_robot">
  <link
    name="base_link">
    <inertial>
      <origin
        xyz="-0.12079 1.3843E-17 0.15582"
        rpy="0 0 0" />
      <mass
        value="5" />
      <inertia
        ixx="0.20526"
        ixy="-4.7032E-18"
        ixz="0.00027898"
        iyy="0.16522"
        iyz="1.1184E-17"
        izz="0.21001" />
    </inertial>
    <visual>
      <origin
        xyz="0 0 0"
        rpy="0 0 0" />
      <geometry>
        <mesh
          filename="package://box_robot/meshes/base_link.STL" />
      </geometry>
      <material
        name="">
        <color
          rgba="0.79216 0.81961 0.93333 1" />
      </material>
    </visual>
    <collision>
      <origin
        xyz="0 0 0"
        rpy="0 0 0" />
      <geometry>
        <mesh
          filename="package://box_robot/meshes/base_link.STL" />
      </geometry>
    </collision>
  </link>
  <link
    name="castor_link">
    <inertial>
      <origin
        xyz="-0.16 -5.5511E-17 -1.9722E-31"
        rpy="0 0 0" />
      <mass
        value="1" />
      <inertia
        ixx="4.0715E-05"
        ixy="0"
        ixz="3.089E-51"
        iyy="4.0715E-05"
        iyz="0"
        izz="4.0715E-05" />
    </inertial>
    <visual>
      <origin
        xyz="0 0 0"
        rpy="0 0 0" />
      <geometry>
        <mesh
          filename="package://box_robot/meshes/castor_link.STL" />
      </geometry>
      <material
        name="">
        <color
          rgba="0.79216 0.81961 0.93333 1" />
      </material>
    </visual>
    <collision>
      <origin
        xyz="0 0 0"
        rpy="0 0 0" />
      <geometry>
        <mesh
          filename="package://box_robot/meshes/castor_link.STL" />
      </geometry>
    </collision>
  </link>
  <joint
    name="castor_joint"
    type="fixed">
    <origin
      xyz="0 0 0"
      rpy="1.5708 0 0" />
    <parent
      link="base_link" />
    <child
      link="castor_link" />
    <axis
      xyz="0 0 0" />
    <dynamics
      damping="0"
      friction="0" />
  </joint>
  <link
    name="right_link">
    <inertial>
      <origin
        xyz="0 6.9389E-18 0.01"
        rpy="0 0 0" />
      <mass
        value="3" />
      <inertia
        ixx="0.00052803"
        ixy="-4.5495E-21"
        ixz="9.1166E-21"
        iyy="0.00052803"
        iyz="-3.6002E-19"
        izz="0.0010359" />
    </inertial>
    <visual>
      <origin
        xyz="0 0 0"
        rpy="0 0 0" />
      <geometry>
        <mesh
          filename="package://box_robot/meshes/right_link.STL" />
      </geometry>
      <material
        name="">
        <color
          rgba="0.79216 0.81961 0.93333 1" />
      </material>
    </visual>
    <collision>
      <origin
        xyz="0 0 0"
        rpy="0 0 0" />
      <geometry>
        <mesh
          filename="package://box_robot/meshes/right_link.STL" />
      </geometry>
    </collision>
  </link>
  <joint
    name="right_joint"
    type="continuous">
    <origin
      xyz="0.12 -0.05 -0.165"
      rpy="-3.1416 0 0" />
    <parent
      link="base_link" />
    <child
      link="right_link" />
    <axis
      xyz="0 0 -1" />
    <dynamics
      damping="0"
      friction="0" />
  </joint>
  <link
    name="left_link">
    <inertial>
      <origin
        xyz="0 6.9389E-18 -0.01"
        rpy="0 0 0" />
      <mass
        value="3" />
      <inertia
        ixx="0.00052803"
        ixy="7.6514E-21"
        ixz="3.4246E-21"
        iyy="0.00052803"
        iyz="-3.5965E-19"
        izz="0.0010359" />
    </inertial>
    <visual>
      <origin
        xyz="0 0 0"
        rpy="0 0 0" />
      <geometry>
        <mesh
          filename="package://box_robot/meshes/left_link.STL" />
      </geometry>
      <material
        name="">
        <color
          rgba="0.79216 0.81961 0.93333 1" />
      </material>
    </visual>
    <collision>
      <origin
        xyz="0 0 0"
        rpy="0 0 0" />
      <geometry>
        <mesh
          filename="package://box_robot/meshes/left_link.STL" />
      </geometry>
    </collision>
  </link>
  <joint
    name="left_joint"
    type="continuous">
    <origin
      xyz="0.12 -0.05 0.165"
      rpy="-3.1416 0 0" />
    <parent
      link="base_link" />
    <child
      link="left_link" />
    <axis
      xyz="0 0 -1" />
    <dynamics
      damping="0"
      friction="0" />
  </joint>
  <link
    name="slider_link">
    <inertial>
      <origin
        xyz="0.155 0.16031 0.005"
        rpy="0 0 0" />
      <mass
        value="0.5" />
      <inertia
        ixx="0.0085213"
        ixy="-6.844E-19"
        ixz="1.0535E-18"
        iyy="0.0080038"
        iyz="1.1008E-20"
        izz="0.016509" />
    </inertial>
    <visual>
      <origin
        xyz="0 0 0"
        rpy="0 0 0" />
      <geometry>
        <mesh
          filename="package://box_robot/meshes/slider_link.STL" />
      </geometry>
      <material
        name="">
        <color
          rgba="0.79216 0.81961 0.93333 1" />
      </material>
    </visual>
    <collision>
      <origin
        xyz="0 0 0"
        rpy="0 0 0" />
      <geometry>
        <mesh
          filename="package://box_robot/meshes/slider_link.STL" />
      </geometry>
    </collision>
  </link>
  <joint
    name="slider_joint"
    type="prismatic">
    <origin
      xyz="0.2 -0.00092584 0.155"
      rpy="3.1416 1.5708 0" />
    <parent
      link="base_link" />
    <child
      link="slider_link" />
    <axis
      xyz="0 1 0" />
    <limit
      lower="0"
      upper="0.3"
      effort="1000"
      velocity="0.5" />
    <dynamics
      damping="0"
      friction="0" />
  </joint>

  <gazebo>
    <plugin filename="libgazebo_ros_diff_drive.so" name="differential_drive_controller">
      <alwaysOn>true</alwaysOn>
      <updateRate>20</updateRate>
      <leftJoint>left_joint</leftJoint>
      <rightJoint>right_joint</rightJoint>
      <wheelSeparation>0.310</wheelSeparation>
      <wheelDiameter>0.16</wheelDiameter>
      <torque>5</torque>
      <commandTopic>cmd_vel</commandTopic>
      <odometryTopic>odom</odometryTopic>
      <odometryFrame>odom</odometryFrame>
      <robotBaseFrame>base_link</robotBaseFrame>
    </plugin>
  </gazebo>

</robot>
