<?xml version="1.0" encoding="utf-8"?>
<!-- This URDF was automatically created by SolidWorks to URDF Exporter! Originally created by Stephen Brawner (brawner@gmail.com) 
     Commit Version: 1.6.0-1-g15f4949  Build Version: 1.6.7594.29634
     For more information, please see http://wiki.ros.org/sw_urdf_exporter -->
<robot
  name="robot_14">
  <link
    name="base_link">
    <inertial>
      <origin
        xyz="0.014544 -0.036582 6.7844E-16"
        rpy="0 0 0" />
      <mass
        value="10.629" />
      <inertia
        ixx="0.10203"
        ixy="-0.004034"
        ixz="-7.6451E-18"
        iyy="0.23912"
        iyz="-3.0533E-18"
        izz="0.15152" />
    </inertial>
    <visual>
      <origin
        xyz="0 0 0"
        rpy="0 0 0" />
      <geometry>
        <mesh
          filename="package://robot_14/meshes/base_link.STL" />
      </geometry>
      <material
        name="">
        <color
          rgba="0.79216 0.81961 0.93333 1" />
      </material>
    </visual>
    <collision>
      <origin
        xyz="0 0 0"
        rpy="0 0 0" />
      <geometry>
        <mesh
          filename="package://robot_14/meshes/base_link.STL" />
      </geometry>
    </collision>
  </link>
  <link
    name="R_Link">
    <inertial>
      <origin
        xyz="0 0 0.01125"
        rpy="0 0 0" />
      <mass
        value="0.69095" />
      <inertia
        ixx="0.0017954"
        ixy="1.9729E-35"
        ixz="3.1782E-19"
        iyy="0.0017954"
        iyz="-6.325E-36"
        izz="0.0035325" />
    </inertial>
    <visual>
      <origin
        xyz="0 0 0"
        rpy="0 0 0" />
      <geometry>
        <mesh
          filename="package://robot_14/meshes/R_Link.STL" />
      </geometry>
      <material
        name="">
        <color
          rgba="0.79216 0.81961 0.93333 1" />
      </material>
    </visual>
    <collision>
      <origin
        xyz="0 0 0"
        rpy="0 0 0" />
      <geometry>
        <mesh
          filename="package://robot_14/meshes/R_Link.STL" />
      </geometry>
    </collision>
  </link>
  <joint
    name="R_Joint"
    type="continuous">
    <origin
      xyz="-0.13201 -0.04 -0.1775"
      rpy="3.1416 0 0" />
    <parent
      link="base_link" />
    <child
      link="R_Link" />
    <axis
      xyz="0 0 1" />
  </joint>
  <link
    name="L_Link">
    <inertial>
      <origin
        xyz="0 0 -0.01125"
        rpy="0 0 0" />
      <mass
        value="0.69095" />
      <inertia
        ixx="0.0017954"
        ixy="1.9729E-35"
        ixz="3.1782E-19"
        iyy="0.0017954"
        iyz="-6.325E-36"
        izz="0.0035325" />
    </inertial>
    <visual>
      <origin
        xyz="0 0 0"
        rpy="0 0 0" />
      <geometry>
        <mesh
          filename="package://robot_14/meshes/L_Link.STL" />
      </geometry>
      <material
        name="">
        <color
          rgba="0.79216 0.81961 0.93333 1" />
      </material>
    </visual>
    <collision>
      <origin
        xyz="0 0 0"
        rpy="0 0 0" />
      <geometry>
        <mesh
          filename="package://robot_14/meshes/L_Link.STL" />
      </geometry>
    </collision>
  </link>
  <joint
    name="L_Joint"
    type="continuous">
    <origin
      xyz="-0.13201 -0.04 0.1775"
      rpy="3.1416 0 0" />
    <parent
      link="base_link" />
    <child
      link="L_Link" />
    <axis
      xyz="0 0 1" />
  </joint>
  <link
    name="Gripper_Link">
    <inertial>
      <origin
        xyz="0.0016926 -0.1525 0.062677"
        rpy="0 0 0" />
      <mass
        value="0.27354" />
      <inertia
        ixx="0.0033211"
        ixy="-2.2412E-20"
        ixz="1.8332E-05"
        iyy="0.00038553"
        iyz="2.878E-19"
        izz="0.0030666" />
    </inertial>
    <visual>
      <origin
        xyz="0 0 0"
        rpy="0 0 0" />
      <geometry>
        <mesh
          filename="package://robot_14/meshes/Gripper_Link.STL" />
      </geometry>
      <material
        name="">
        <color
          rgba="0.79216 0.81961 0.93333 1" />
      </material>
    </visual>
    <collision>
      <origin
        xyz="0 0 0"
        rpy="0 0 0" />
      <geometry>
        <mesh
          filename="package://robot_14/meshes/Gripper_Link.STL" />
      </geometry>
    </collision>
  </link>
  <joint
    name="Gripper_Joint"
    type="fixed">
    <origin
      xyz="0.22986 0.05 0.1525"
      rpy="1.5708 0 0" />
    <parent
      link="base_link" />
    <child
      link="Gripper_Link" />
    <axis
      xyz="0 0 0" />
  </joint>
  <link
    name="Slider_Link">
    <inertial>
      <origin
        xyz="0.1525 0.19953 -0.048118"
        rpy="0 0 0" />
      <mass
        value="0.1" />
      <inertia
        ixx="0.0046159"
        ixy="-4.0549E-18"
        ixz="2.1001E-18"
        iyy="0.0098749"
        iyz="0.0001874"
        izz="0.013164" />
    </inertial>
    <visual>
      <origin
        xyz="0 0 0"
        rpy="0 0 0" />
      <geometry>
        <mesh
          filename="package://robot_14/meshes/Slider_Link.STL" />
      </geometry>
      <material
        name="">
        <color
          rgba="0.79216 0.81961 0.93333 1" />
      </material>
    </visual>
    <collision>
      <origin
        xyz="0 0 0"
        rpy="0 0 0" />
      <geometry>
        <mesh
          filename="package://robot_14/meshes/Slider_Link.STL" />
      </geometry>
    </collision>
  </link>
  <joint
    name="Slider_Joint"
    type="revolute">
    <origin
      xyz="0.04 0 0.11"
      rpy="-0.0096521 0 -1.5708" />
    <parent
      link="Gripper_Link" />
    <child
      link="Slider_Link" />
    <axis
      xyz="1 0 0" />
    <limit
      lower="-3"
      upper="-0.5"
      effort="1000"
      velocity="0.5" />
  </joint>
  <link
    name="Laser_Link">
    <inertial>
      <origin
        xyz="0 0 0"
        rpy="0 0 0" />
      <mass
        value="0" />
      <inertia
        ixx="0"
        ixy="0"
        ixz="0"
        iyy="0"
        iyz="0"
        izz="0" />
    </inertial>
    <visual>
      <origin
        xyz="0 0 0"
        rpy="0 0 0" />
      <geometry>
        <mesh
          filename="package://robot_14/meshes/Laser_Link.STL" />
      </geometry>
      <material
        name="">
        <color
          rgba="1 1 1 1" />
      </material>
    </visual>
    <collision>
      <origin
        xyz="0 0 0"
        rpy="0 0 0" />
      <geometry>
        <mesh
          filename="package://robot_14/meshes/Laser_Link.STL" />
      </geometry>
    </collision>
  </link>
  <joint
    name="Laser_Joint"
    type="fixed">
    <origin
      xyz="0.18485 -0.08 0.025"
      rpy="1.5708 1.5708 0" />
    <parent
      link="base_link" />
    <child
      link="Laser_Link" />
    <axis
      xyz="0 0 0" />
  </joint>
  <link
    name="Camera_Link">
    <inertial>
      <origin
        xyz="-0.0004896 1.1762E-08 0.037068"
        rpy="0 0 0" />
      <mass
        value="0.091097" />
      <inertia
        ixx="5.2948E-05"
        ixy="-1.0409E-10"
        ixz="5.7682E-07"
        iyy="5.2324E-05"
        iyz="3.5273E-12"
        izz="1.8086E-05" />
    </inertial>
    <visual>
      <origin
        xyz="0 0 0"
        rpy="0 0 0" />
      <geometry>
        <mesh
          filename="package://robot_14/meshes/Camera_Link.STL" />
      </geometry>
      <material
        name="">
        <color
          rgba="0.79216 0.81961 0.93333 1" />
      </material>
    </visual>
    <collision>
      <origin
        xyz="0 0 0"
        rpy="0 0 0" />
      <geometry>
        <mesh
          filename="package://robot_14/meshes/Camera_Link.STL" />
      </geometry>
    </collision>
  </link>
  <joint
    name="Camera_Joint"
    type="fixed">
    <origin
      xyz="0.025 -0.025 0.1"
      rpy="0 0 1.5708" />
    <parent
      link="Laser_Link" />
    <child
      link="Camera_Link" />
    <axis
      xyz="0 0 0" />
  </joint>
</robot>